Workbook

Sheet Resumo
A1: Graph-Driven Exam Gen - Corpus de itens gerados (1.788 itens, 120 habilidades, 3 condicoes)
A3: Total de itens | B3: =COUNTA(Questoes!A2:A100000)
A4: Itens validos estruturalmente | B4: =COUNTIF(Questoes!P2:P100000,TRUE)
A6: Condicao | B6: Qtd. itens | C6: C(i,h) media | D6: E(i,h) media | E6: TTR media | F6: FKGL media | G6: Juiz principal (glm-4-plus) media | H6: Juiz secundario (glm-4.5) media
A7: com_grafo | B7: =COUNTIF(Questoes!B2:B100000,"com_grafo") | C7: =AVERAGEIF(Questoes!B2:B100000,"com_grafo",Questoes!Q2:Q100000) | D7: =AVERAGEIF(Questoes!B2:B100000,"com_grafo",Questoes!R2:R100000) | E7: =AVERAGEIF(Questoes!B2:B100000,"com_grafo",Questoes!S2:S100000) | F7: =AVERAGEIF(Questoes!B2:B100000,"com_grafo",Questoes!T2:T100000) | G7: =AVERAGEIF(Questoes!B2:B100000,"com_grafo",Questoes!U2:U100000) | H7: =AVERAGEIF(Questoes!B2:B100000,"com_grafo",Questoes!AB2:AB100000)
A8: com_fewshot_sem_grafo | B8: =COUNTIF(Questoes!B2:B100000,"com_fewshot_sem_grafo") | C8: =AVERAGEIF(Questoes!B2:B100000,"com_fewshot_sem_grafo",Questoes!Q2:Q100000) | D8: =AVERAGEIF(Questoes!B2:B100000,"com_fewshot_sem_grafo",Questoes!R2:R100000) | E8: =AVERAGEIF(Questoes!B2:B100000,"com_fewshot_sem_grafo",Questoes!S2:S100000) | F8: =AVERAGEIF(Questoes!B2:B100000,"com_fewshot_sem_grafo",Questoes!T2:T100000) | G8: =AVERAGEIF(Questoes!B2:B100000,"com_fewshot_sem_grafo",Questoes!U2:U100000) | H8: =AVERAGEIF(Questoes!B2:B100000,"com_fewshot_sem_grafo",Questoes!AB2:AB100000)
A9: sem_grafo | B9: =COUNTIF(Questoes!B2:B100000,"sem_grafo") | C9: =AVERAGEIF(Questoes!B2:B100000,"sem_grafo",Questoes!Q2:Q100000) | D9: =AVERAGEIF(Questoes!B2:B100000,"sem_grafo",Questoes!R2:R100000) | E9: =AVERAGEIF(Questoes!B2:B100000,"sem_grafo",Questoes!S2:S100000) | F9: =AVERAGEIF(Questoes!B2:B100000,"sem_grafo",Questoes!T2:T100000) | G9: =AVERAGEIF(Questoes!B2:B100000,"sem_grafo",Questoes!U2:U100000) | H9: =AVERAGEIF(Questoes!B2:B100000,"sem_grafo",Questoes!AB2:AB100000)
A11: Notas
A12: Juiz principal: glm-4-plus, distinto do gerador (julgamento em 02/10/2026). Juiz secundario: glm-4.5, o proprio gerador (execucao original). Notas de 1 a 5 em cada dimensao; a media e a media simples das cinco dimensoes.
A13: Similaridade semantica nao calculada: a chave de API utilizada nao tinha acesso a modelos de embedding.
A14: Respostas brutas, consumo de tokens e horario de cada julgamento do juiz principal: data/julgamento_glm-4-plus.jsonl.

Sheet Questoes
A1: ID | B1: Condicao | C1: Area (codigo) | D1: Area (nome) | E1: Competencia | F1: Habilidade | G1: Habilidade (descricao) | H1: Enunciado | I1: Alternativa A | J1: Alternativa B | K1: Alternativa C | L1: Alternativa D | M1: Alternativa E | N1: Gabarito | O1: Justificativa (gerador) | P1: Validacao estrutural OK | Q1: Cobertura lexical C(i,h) | R1: Especificidade curricular E(i,h) | S1: TTR | T1: FKGL | U1: Juiz principal (glm-4-plus) - media | V1: Principal D1 - Alinhamento a habilidade | W1: Principal D2 - Adequacao dos OCs | X1: Principal D3 - Plausibilidade dos distratores | Y1: Principal D4 - Nivel de escolaridade | Z1: Principal D5 - Formato ENEM | AA1: Principal - justificativa | AB1: Juiz secundario (glm-4.5) - media | AC1: Secundario D1 | AD1: Secundario D2 | AE1: Secundario D3 | AF1: Secundario D4 | AG1: Secundario D5 | AH1: Secundario - justificativa
A2: 713f511f-a0bd-4881-be84-46400bae4495 | B2: com_grafo | C2: CH | D2: Ciencias Humanas e suas Tecnologias | E2: 1 | F2: CH-H1 | G2: Interpretar historicamente e/ou geograficamente fontes documentais acerca de aspectos da cultura. | H2: Durante o século XVI, missionários jesuítas enviaram cartas à Europa descrevendo os costumes dos povos nativos da terra que viria a ser o Brasil. Em um trecho de uma dessas cartas, o padre Manuel da Nóbrega relata: 'Estes índios andam nus sem nenhuma cobertura, nem sabem ter Rei, nem Lei, nem terem paredes de casas, nem se alimentam de pão, mas da carne que caçam e das frutas da terra, e vivem como bestas, sem entendimento das coisas de Deus.' A análise desse documento histórico permite identificar que a perspectiva do autor sobre a cultura indígena era marcada por: | I2: Um interesse antropológico em preservar as tradições locais para o estudo da diversidade humana. | J2: Uma postura de admiração pela liberdade dos costumes indígenas em oposição aos rigores da sociedade europeia. | K2: Um viés etnocêntrico que julgava a cultura indígena inferior para justificar a dominação e a catequese. | L2: Uma tentativa objetiva de descrever a organização política democrática das tribos locais. | M2: Um reconhecimento da adaptação sustentável dos povos indígenas ao ambiente natural da América Portuguesa. | N2: C | O2: A questão exige a interpretação histórica de uma fonte documental (Habilidade H1). O relato de Nóbrega reflete o etnocentrismo europeu, que utilizava os padrões culturais da Europa (presença de Rei, Lei, fé cristã, vestimentas, arquitetura de pedra) como parâmetro para julgar outras sociedades. Ao classificar os indígenas como 'bestas' e desprovidos de civilização, o autor desqualifica a cultura local para legitimar a necessidade de intervenção, dominação e conversão religiosa. | P2: TRUE | Q2: 0.053191489 | R2: 2.4213836 | S2: 0.8952381 | T2: 15.673985 | U2: 4.8 | V2: 5 | W2: 5 | X2: 4 | Y2: 5 | Z2: 5 | AA2: O item apresenta excelente alinhamento com a habilidade-alvo CH-H1, pois exige a interpretação histórica de uma fonte documental para compreender a perspectiva do autor sobre a cultura indígena. Os objetos de conhecimento esperados (diversidade cultural, conflitos e vida em sociedade) são perfeitamente contemplados, pois o texto aborda a diversidade cultural e os conflitos inerentes ao processo de colonização. Os distratores são plausíveis, pois exploram interpretações equivocadas mas com algum fundamento no texto (como a menção à adaptação ao ambiente na alternativa E), embora a alternativa A seja menos provável devido ao tom claramente preconceituoso do relato. O item é adequado ao nível de escolaridade do Ensino Médio, pois envolve a análise de um documento histórico e o reconhecimento de conceitos como etnocentrismo. A aderência ao formato ENEM é máxima, pois segue a estrutura clássica de apresentar um documento e pedir sua interpretação, com uma questão de múltipla escolha que exige pensamento crítico. | AB2: 5 | AC2: 5 | AD2: 5 | AE2: 5 | AF2: 5 | AG2: 5 | AH2: O item apresenta uma fonte primária clássica (carta jesuítica) e exige do aluno a identificação da perspectiva do autor (etnocentrismo) a partir da análise do texto. Há um alinhamento perfeito com a habilidade CH-H1 (interpretação histórica de fontes documentais sobre cultura). Os objetos de conhecimento (diversidade cultural, conflitos) são contemplados na discussão sobre o choque entre visões de mundo. Os distratores são bem elaborados, explorando anacronismos (antropologia moderna, sustentabilidade) ou interpretações equivocadas do texto (democracia, admiração), exigindo leitura atenta e domínio de conteúdo histórico do Ensino Médio. O formato segue rigorosamente os padrões do ENEM.
A3: 464413e3-d59e-4e3c-994a-d7025b4ec0a2 | B3: com_grafo | C3: CH | D3: Ciencias Humanas e suas Tecnologias | E3: 1 | F3: CH-H1 | G3: Interpretar historicamente e/ou geograficamente fontes documentais acerca de aspectos da cultura. | H3: No século XVI, o cronista português Pero de Magalhães Gândavo escreveu sobre os habitantes da Terra de Santa Cruz: 'Não têm lei, nem rei, nem templo, nem ídolos de pedra ou madeira a quem adorem. Andam nus, sem cobertura alguma. Não lavram a terra, nem plantam, nem têm haveres de espécie alguma. Vivem de caça e de frutos silvestres e da pesca.' Considerando o contexto da conquista da América e a natureza do documento apresentado, a análise desse trecho permite concluir que: | I3: A ausência de templos materiais e de reis confirmava a tese, vigente na época, de que os povos indígenas não possuíam qualquer forma de organização social ou religiosa. | J3: A descrição dos hábitos de vida indígenas, como o nomadismo e a caça, demonstrava uma tentativa objetiva e isenta de compreender a biodiversidade local. | K3: O olhar do colonizador, pautado no etnocentrismo europeu, interpretava erroneamente a diversidade cultural indígena como ausência de cultura e civilização. | L3: A crítica à nudez e à falta de propriedade privada revelava que os indígenas já haviam assimilado os valores humanistas europeus antes da chegada dos jesuítas. | M3: A inexistência de 'lei' e 'rei' citada no documento comprovava que as sociedades indígenas viviam em um estado de natureza caracterizado pela guerra de todos contra todos. | N3: C | O3: A questão exige a habilidade CH-H1, pois solicita a interpretação histórica de uma fonte documental (a crônica de Gândavo) para compreender aspectos da cultura indígena. O aluno deve identificar que o autor, ao julgar os povos nativos pelos padrões europeus (etnocentrismo), não reconhece as complexas estruturas sociais, políticas e espirituais das sociedades indígenas, interpretando suas diferenças culturais (como a ausência de propriedade privada ou de templos físicos) como primitivismo ou carência de organização. | P3: TRUE | Q3: 0.071428571 | R3: 2.8426396 | S3: 0.85496183 | T3: 15.44087 | U3: 5 | V3: 5 | W3: 5 | X3: 5 | Y3: 5 | Z3: 5 | AA3: O item demonstra excelente alinhamento com a habilidade-alvo CH-H1, pois a tarefa central é a interpretação histórica de uma fonte documental (crônica de Gândavo) para analisar aspectos da cultura indígena, exigindo a compreensão do contexto de produção do documento. Os objetos de conhecimento esperados (diversidade cultural, conflitos e vida em sociedade) são perfeitamente adequados, pois a questão aborda justamente a diversidade cultural e os conflitos gerados pelo etnocentrismo europeu. Os distratores são plausíveis e funcionam efetivamente como armadilhas: a alternativa A reproduz o erro do cronista, a B sugere uma neutralidade inexistente, a D apresenta uma anacronismo e a E aplica um conceito filosófico inadequado. O nível de complexidade é adequado para o Ensino Médio, exigindo análise de fonte e contextualização histórica, sem ser excessivamente simplista. A aderência ao formato ENEM é máxima, com enunciado claro, fonte histórica relevante, alternativas que exigem interpretação crítica e uma chave de correção (C) que aponta para a superação de uma visão etnocêntrica, um tema recorrente na prova. | AB3: 4.8 | AC3: 5 | AD3: 5 | AE3: 4 | AF3: 5 | AG3: 5 | AH3: O item está perfeitamente alinhado à habilidade CH-H1, pois solicita a interpretação histórica de uma fonte primária (crônica do século XVI) para identificar o viés etnocêntrico do colonizador diante da diversidade cultural indígena. Os objetos de conhecimento sobre diversidade cultural, conflitos e vida em sociedade são integralmente cobertos. Os distratores A e E são plausíveis, explorando a leitura literal do documento e a aplicação anacrônica de conceitos filosóficos, respectivamente, embora B e D sejam menos consistentes. O nível de dificuldade, o vocabulário e a estrutura seguem rigorosamente o padrão do ENEM.
A4: ce620140-875a-4107-911c-7c8b6b5514db | B4: com_grafo | C4: CH | D4: Ciencias Humanas e suas Tecnologias | E4: 1 | F4: CH-H1 | G4: Interpretar historicamente e/ou geograficamente fontes documentais acerca de aspectos da cultura. | H4: Durante uma aula sobre a diversidade cultural brasileira, a professora apresentou aos alunos um trecho de uma carta do século XVI, escrita pelo jesuíta Manuel da Nóbrega: 'Estes gentios são de tão má condição que, se lhes não meterem o freio da lei e da justiça, não haverá neles nenhum bem. Não têm rei, nem lei, nem walls, nem dinheiro, e vivem segundo a natureza, sem se preocuparem com o futuro.' A partir da análise histórica desse documento, é possível identificar que a visão do colonizador sobre a cultura indígena era marcada por: | I4: Um reconhecimento da liberdade e da harmonia com a natureza existentes na sociedade nativa, que serviam de modelo para os europeus. | J4: Uma postura de tolerância religiosa, que aceitava as diferenças espirituais dos povos originários como formas válidas de fé. | K4: Um etnocentrismo europeu que julgava a organização social indígena como inferior e desordenada por não se adequar aos padrões ocidentais. | L4: Uma tentativa de compreensão antropológica isenta, que buscava entender as estruturas políticas e econômicas locais sem julgamentos. | M4: Um elogio à simplicidade material dos povos indígenas, vista como uma virtude moral em contraposição à ganância europeia. | N4: C | O4: A habilidade CH-H1 é exercitada ao interpretar a fonte documental (a carta jesuíta) para compreender o olhar do colonizador sobre a cultura indígena. O texto revela um viés etnocêntrico, pois o autor avalia a sociedade nativa ('má condição', 'sem lei', 'sem rei') tendo como parâmetro exclusivo os valores e instituições da sociedade europeia da época, desconsiderando a especificidade e a complexidade da organização social dos povos originários. | P4: TRUE | Q4: 0.085714286 | R4: 3.6096257 | S4: 0.92105263 | T4: 17.166539 | U4: 5 | V4: 5 | W4: 5 | X4: 5 | Y4: 5 | Z4: 5 | AA4: O item demonstra excelente alinhamento com a habilidade CH-H1, pois a tarefa central é interpretar uma fonte documental histórica para compreender uma perspectiva sobre a cultura indígena. Os objetos de conhecimento esperados (diversidade cultural, conflitos e vida em sociedade) são perfeitamente contemplados, pois o texto aborda o conflito entre culturas e a visão sobre a organização social. Os distratores são plausíveis e funcionais: a alternativa A inverte o sentido do texto, a B e a D atribuem ao autor uma postura de neutralidade ou abertura que ele não demonstra, e a E capta um fragmento positivo ('vivem segundo a natureza') mas ignora o julgamento negativo geral ('má condição'). O nível de complexidade é adequado ao Ensino Médio, exigindo a compreensão de um texto histórico e a identificação de um conceito-chave (etnocentrismo). O formato segue rigorosamente as especificações do ENEM, com enunciado claro, fonte documental relevante, questão de interpretação e alternativas bem elaboradas. | AB4: 5 | AC4: 5 | AD4: 5 | AE4: 5 | AF4: 5 | AG4: 5 | AH4: O item apresenta uma fonte documental histórica (carta de Manuel da Nóbrega) e solicita a interpretação da visão do colonizador sobre a cultura indígena, o que está em perfeita consonância com a habilidade CH-H1 (interpretar fontes documentais sobre aspectos da cultura). O objeto de conhecimento (diversidade cultural e conflitos) é abordado de forma direta ao expor o choque entre a visão europeia e a organização social indígena. Os distratores são bem elaborados, explorando conceitos como o 'bom selvagem' (A e E) ou o anacronismo da tolerância religiosa (B), exigindo do aluno a leitura atenta do texto para identificar o viés etnocêntrico apontado no gabarito (C). O vocabulário e o contexto histórico são adequados ao Ensino Médio, e a estrutura segue rigorosamente o padrão do ENEM.
A5: 6acbe816-2db7-4766-a114-3f6bd41da59e | B5: com_grafo | C5: CH | D5: Ciencias Humanas e suas Tecnologias | E5: 1 | F5: CH-H1 | G5: Interpretar historicamente e/ou geograficamente fontes documentais acerca de aspectos da cultura. | H5: No século XVI, o cronista português Pero de Magalhães Gândavo escreveu sobre os habitantes da terra recém-descoberta: 'Não têm lei, nem rei, nem templo, nem ídolos de pedra ou madeira a quem adorem. Andam nus, sem cobertura alguma. Não lavram a terra, nem plantam, nem têm haveres de espécie alguma. Vivem de caça e de frutos silvestres e da pesca. São muito dados à folgança e à bebedeira, quando acham vinho ou cauim.' Considerando o contexto histórico da conquista da América e a natureza do documento apresentado, a análise desse trecho permite concluir que: | I5: A ausência de templos materiais e de reis confirmava a tese de que os povos indígenas não possuíam qualquer forma de organização social ou religiosa, vivendo em um estado de natureza primitivo. | J5: A descrição dos hábitos de caça e coleta demonstrava uma tentativa objetiva do cronista em compreender a adaptação dos povos nativos ao ecossistema local, sem juízos de valor. | K5: O olhar do colonizador, marcado pelo etnocentrismo europeu, impedia o reconhecimento de estruturas socioculturais complexas diferentes das ocidentais, como as baseadas no parentesco e na oralidade. | L5: A crítica à nudez e à 'folgança' tinha como objetivo principal defender a integração dos indígenas à sociedade colonial através da adoção imediata do trabalho assalariado urbano. | M5: A inexistência de propriedade privada e de acumulação de riquezas, citada no texto, era uma prova de que os indígenas já haviam desenvolvido um sistema social comunista antes da chegada dos europeus. | N5: C | O5: A questão exige a interpretação histórica de uma fonte documental (a crônica de Gândavo) para compreender aspectos da cultura indígena e o choque com a europeia. O item C está correto porque identifica o viés etnocêntrico do autor, que avalia a cultura indígena pelos padrões europeus (lei, rei, templo, propriedade), deixando de perceber a lógica própria de organização social e política das sociedades tupis. Isso atende à habilidade CH-H1 de interpretar fontes documentais acerca de aspectos da cultura. | P5: TRUE | Q5: 0.037313433 | R5: 2.014218 | S5: 0.88741722 | T5: 15.306732 | U5: 4.8 | V5: 5 | W5: 5 | X5: 4 | Y5: 5 | Z5: 5 | AA5: O item apresenta excelente alinhamento com a habilidade CH-H1, pois a tarefa central é a interpretação de uma fonte documental histórica para compreender aspectos da cultura indígena e o olhar do colonizador. Os objetos de conhecimento (diversidade cultural, conflitos e vida em sociedade) são perfeitamente adequados e operacionalizados no enunciado e na alternativa correta. Os distratores são plausíveis, pois exploram visões simplistas e anacrônicas frequentemente associadas ao período (A, D, E) e uma suposta neutralidade (B), funcionando como bons desafios para o estudante que não compreende o contexto de produção da fonte. O nível de complexidade é adequado ao Ensino Médio, exigindo a compreensão de conceitos como etnocentrismo e análise de fontes históricas. A aderência ao formato ENEM é máxima, com um enunciado claro, uma fonte histórica relevante, alternativas que exigem análise crítica e uma justificativa robusta para a resposta correta. | AB5: 5 | AC5: 5 | AD5: 5 | AE5: 5 | AF5: 5 | AG5: 5 | AH5: O item apresenta excelente alinhamento à habilidade CH-H1, pois exige a interpretação histórica de uma fonte primária (crônica do século XVI) para identificar o viés etnocêntrico do colonizador e a diversidade das estruturas socioculturais indígenas. Os objetos de conhecimento (diversidade cultural e conflitos) são integralmente abordados na análise do choque entre visões de mundo. Os distratores são plausíveis e bem elaborados, explorando erros comuns como a leitura literal do documento (A e B), o anacronismo (E) e a extrapolação indevida de contextos econômicos (D). O nível de exigência é adequado ao Ensino Médio, exigindo domínio de conceitos como etnocentrismo e organização social baseada no parentesco. A estrutura, o enunciado e o comando seguem rigorosamente o padrão das provas do ENEM.
A6: d66852ea-097c-4a88-83ee-8316b037f15e | B6: com_grafo | C6: CH | D6: Ciencias Humanas e suas Tecnologias | E6: 1 | F6: CH-H1 | G6: Interpretar historicamente e/ou geograficamente fontes documentais acerca de aspectos da cultura. | H6: No século XVI, o cronista português Pero de Magalhães Gândavo escreveu sobre os habitantes da terra recém-descoberta: 'Não têm lei, nem rei, nem templo, nem ídolos de pedra ou madeira a quem adorem. Andam nus, sem cobertura alguma. Não lavram a terra, nem plantam, nem têm haveres de espécie alguma. Vivem de caça e de frutos silvestres e da pesca. São muito dados à folgança e à bebedeira, quando acham vinho ou cauim.' Considerando o contexto da conquista da América e a natureza do documento apresentado, a análise desse trecho permite concluir que: | I6: A ausência de propriedade privada e de templos materiais comprovava a inexistência de qualquer forma de organização social ou religiosa entre os povos indígenas. | J6: A descrição dos hábitos indígenas, como a nudez e o nomadismo, demonstrava uma tentativa objetiva e respeitosa de compreender a lógica interna da cultura nativa. | K6: O olhar do colonizador, marcado pelo etnocentrismo europeu, interpretava erroneamente a diversidade cultural indígena como ausência de cultura e de civilização. | L6: A crítica à 'folgança' e à 'bebedeira' indicava que os povos indígenas possuíam uma cultura material muito mais desenvolvida do que a dos europeus, gerando inveja nos cronistas. | M6: A falta de um 'rei' ou 'lei' escrita justificava a imediata escravização dos indígenas, pois eles eram biologicamente incapazes de se adaptarem ao trabalho agrícola. | N6: C | O6: A questão exige a interpretação histórica de uma fonte documental (a crônica de Gândavo) para compreender os aspectos culturais dos povos indígenas e o conflito com os europeus. O item correto (C) identifica que o autor, ao julgar os indígenas pelos padrões europeus (propriedade, Estado, religião institucionalizada), não reconhece as especificidades da organização sociocultural indígena, caracterizando o etnocentrismo típico do período colonial. Isso atende à habilidade CH-H1 de interpretar fontes documentais acerca de aspectos da cultura. | P6: TRUE | Q6: 0.068965517 | R6: 3.3580247 | S6: 0.85294118 | T6: 15.177519 | U6: 5 | V6: 5 | W6: 5 | X6: 5 | Y6: 5 | Z6: 5 | AA6: O item apresenta excelente alinhamento com a habilidade CH-H1, pois a tarefa central é a interpretação histórica de uma fonte documental para analisar aspectos da cultura indígena e o conflito gerado pelo olhar do colonizador. Os objetos de conhecimento (diversidade cultural, conflitos e vida em sociedade) estão perfeitamente adequados e são mobilizados para a resolução do item. Os distratores são plausíveis e funcionam como armadilhas bem construídas: a alternativa A reproduz a visão etnocêntrica do texto, a B sugere uma neutralidade inexistente, a D inverte a lógica da fonte e a E aponta para uma consequência histórica, mas não para a interpretação da cultura. O nível de complexidade é adequado para o Ensino Médio, exigindo a compreensão de conceitos como etnocentrismo e análise de fontes históricas. A aderência ao formato ENEM é total, com enunciado claro, fonte contextualizada, alternativas que exigem interpretação crítica e uma resposta que aponta para a compreensão do processo histórico de colonização. | AB6: 5 | AC6: 5 | AD6: 5 | AE6: 5 | AF6: 5 | AG6: 5 | AH6: O item apresenta excelência em todos os critérios avaliados. Está perfeitamente alinhado à habilidade CH-H1, pois exige a interpretação histórica de uma fonte documental (crônica) para identificar o viés etnocentrismo do colonizador diante da diversidade cultural indígena. Os objetos de conhecimento (diversidade cultural e conflitos) são integralmente abordados através da análise do choque entre visões de mundo. Os distratores são bem elaborados e plausíveis, testando erros comuns como a tomada do discurso eurocêntrico como verdade absoluta (A) ou a naturalização da fonte como neutra (B). O nível de complexidade e a linguagem são adequados ao Ensino Médio, e o formato segue rigorosamente os padrões do ENEM.
A7: 5b7aefe2-f69c-4abb-86c9-94dda1a698a4 | B7: com_grafo | C7: CH | D7: Ciencias Humanas e suas Tecnologias | E7: 2 | F7: CH-H10 | G7: Reconhecer a dinamica da organizacao dos movimentos sociais e a importancia da participacao da coletividade na transformacao da realidade historico-geografica. | H7: Em uma grande metrópole brasileira, uma comunidade residente em uma área periférica, historicamente marcada pela ausência de políticas públicas e pela ameaça de remoção devido à especulação imobiliária, decidiu se organizar. Através de assembleias periódicas, da criação de comissões de negociação e da mobilização de moradores em manifestações e ocupações de espaços públicos, o grupo conseguiu pressionar o poder público. Como resultado, o governo estadual sancionou um decreto de regularização fundiária e iniciou obras de infraestrutura urbana na localidade. | I7: A ineficácia das ações coletivas diante da rigidez das leis de mercado imobiliário. | J7: A substituição das atribuições do Estado por iniciativas de caridade privada. | K7: A dinâmica da organização dos movimentos sociais na transformação da realidade histórico-geográfica. | L7: A predominância do individualismo sobre a solidariedade na resolução de conflitos urbanos. | M7: A impossibilidade de alteração da ordem estabelecida sem o uso de conflitos armados. | N7: C | O7: A questão descreve um processo no qual a organização coletiva e a mobilização social (assembleias, comissões, manifestações) resultam em mudanças concretas no espaço geográfico (regularização fundiária, obras de infraestrutura) e na relação de poder com o Estado. Isso exige do aluno o reconhecimento de como os movimentos sociais se estruturam e atuam, conforme estabelece a habilidade CH-H10, que foca na importância da participação da coletividade na transformação da realidade histórico-geográfica. | P7: TRUE | Q7: 0.073170732 | R7: 2.3612903 | S7: 0.98795181 | T7: 15.762143 | U7: 5 | V7: 5 | W7: 5 | X7: 5 | Y7: 5 | Z7: 5 | AA7: O item apresenta excelente alinhamento com a habilidade-alvo CH-H10, pois descreve um processo claro de organização coletiva (assembleias, comissões) que leva à transformação da realidade histórico-geográfica (regularização fundiária, obras de infraestrutura). Os objetos de conhecimento esperados (formas de organização social, movimentos sociais, ação do Estado e representação espacial) estão plenamente contemplados no enunciado. Os distratores são plausíveis e funcionam como armadilhas conceituais bem definidas: A) nega a eficácia da ação coletiva; B) confunde ação social com caridade privada; D) prioriza o individualismo; E) defende a violência como única solução. A linguagem e a complexidade do problema são adequadas ao Ensino Médio, exigindo análise de contexto e compreensão de processos sociais. O formato segue o padrão ENEM, com um texto contextualizado, alternativas que exigem interpretação crítica e uma resposta que sintetiza o cerne do fenômeno descrito. | AB7: 4.6 | AC7: 5 | AD7: 5 | AE7: 3 | AF7: 5 | AG7: 5 | AH7: O item apresenta alinhamento perfeito à habilidade CH-H10, descrevendo um cenário de organização coletiva que resulta em transformação espacial. Os objetos de conhecimento (movimentos sociais, ação do Estado) são adequadamente abordados. O nível de escolaridade é compatível, e o formato segue o padrão ENEM. No entanto, os distratores são pouco plausíveis, pois contradizem diretamente o enunciado ou introduzem conceitos estranhos ao texto (caridade, conflito armado), o que facilita excessivamente a eliminação das alternativas incorretas.
A8: e444be20-88b7-4950-92fa-403fbc7167cb | B8: com_grafo | C8: CH | D8: Ciencias Humanas e suas Tecnologias | E8: 2 | F8: CH-H10 | G8: Reconhecer a dinamica da organizacao dos movimentos sociais e a importancia da participacao da coletividade na transformacao da realidade historico-geografica. | H8: Em uma grande metrópole brasileira, um grupo de moradores de uma comunidade periférica, insatisfeito com a ausência de políticas públicas de saneamento básico e transporte, decidiu se organizar coletivamente. Através de assembleias populares e do uso de redes sociais, a comunidade elaborou um plano de reivindicações e realizou manifestações pacíficas que ganharam visibilidade nacional. Como resultado dessa mobilização, o governo municipal foi pressionado a iniciar as obras de infraestrutura na região. Essa situação ilustra a importância da participação social na transformação da realidade, pois demonstra que: | I8: os conflitos urbanos devem ser resolvidos exclusivamente pela intervenção do Poder Judiciário, sem a necessidade de mobilização popular. | J8: a organização da sociedade civil é capaz de influenciar decisões políticas e alterar a dinâmica do espaço geográfico. | K8: as manifestações populares são instrumentos ineficazes, visto que o Estado atua de forma independente da pressão social. | L8: a segregação espacial nas cidades é um processo natural que não pode ser revertido pela ação de movimentos sociais. | M8: a participação política deve ser restrita ao período eleitoral, garantindo a ordem e a estabilidade das instituições. | N8: B | O8: A questão aborda a habilidade CH-H10 ao apresentar um cenário onde a organização coletiva (movimento social) atua na transformação da realidade histórico-geográfica (melhoria na infraestrutura e ocupação do espaço). A alternativa correta destaca o papel da sociedade civil na influência das políticas públicas e na modificação do espaço, reconhecendo a dinâmica dos movimentos sociais como agentes de mudança. | P8: TRUE | Q8: 0.081632653 | R8: 2.5627706 | S8: 0.9245283 | T8: 16.810964 | U8: 5 | V8: 5 | W8: 5 | X8: 5 | Y8: 5 | Z8: 5 | AA8: O item apresenta excelente alinhamento com a habilidade-alvo CH-H10, pois descreve um movimento social organizado que, através da ação coletiva, promove a transformação da realidade histórico-geográfica (infraestrutura urbana). Os objetos de conhecimento esperados (organização social, movimentos sociais, ação do Estado e representação espacial) estão plenamente contemplados no enunciado e na alternativa correta. Os distratores são plausíveis e funcionais, pois representam visões contrárias ou simplificadas sobre a participação social e a dinâmica urbana (intervenção judicial, ineficácia das manifestações, naturalização da segregação, restrição ao período eleitoral), exigindo do estudante a compreensão crítica do tema. A linguagem e o contexto são adequados ao nível de escolaridade do Ensino Médio, abordando um problema urbano real e relevante. A estrutura do item, com seu enunciado contextualizado e alternativas que exigem análise de causa e consequência, está em total aderência ao formato característico das questões de Humanas do ENEM. | AB8: 5 | AC8: 5 | AD8: 5 | AE8: 5 | AF8: 5 | AG8: 5 | AH8: O item avalia com precisão a habilidade CH-H10, ao exigir o reconhecimento da relação entre organização coletiva e transformação da realidade espacial. O enunciado é contextualizado e atual, abordando os objetos de conhecimento previstos (movimentos sociais e ação do Estado). Os distratores são bem elaborados, baseando-se em concepções teóricas equivocadas ou contrárias ao texto, como a ineficácia da mobilização ou o determinismo geográfico. O vocabulário e a complexidade são adequados ao Ensino Médio, e a estrutura do item segue fielmente o modelo do ENEM.
A9: 6ce6a12f-1676-4d96-a869-8ba1c65f0381 | B9: com_grafo | C9: CH | D9: Ciencias Humanas e suas Tecnologias | E9: 2 | F9: CH-H10 | G9: Reconhecer a dinamica da organizacao dos movimentos sociais e a importancia da participacao da coletividade na transformacao da realidade historico-geografica. | H9: Em diversas capitais brasileiras, movimentos sociais organizados têm realizado ocupações de prédios abandonados no centro urbano. Essas ações não visam apenas ao abrigo imediato, mas também à criação de espaços de convivência, cultura e resistência. Através de assembleias e mutirões, os moradores estruturam a gestão coletiva dos espaços e reivindicam do poder público a regularização da posse e o direito à moradia digna. | I9: A ineficácia das políticas públicas habitacionais, que torna a invasão de propriedades a única alternativa para a sobrevivência individual. | J9: A desorganização do espaço urbano, resultante da ausência de leis que regulamentem o uso do solo e a propriedade privada nas metrópoles. | K9: A dinâmica dos movimentos sociais na transformação da realidade espacial, utilizando a organização coletiva para reivindicar direitos e redefinir o uso da cidade. | L9: O isolamento das comunidades periféricas em relação ao centro, impedindo a integração social e a participação política dos moradores ocupantes. | M9: A substituição das funções do Estado por iniciativas privadas, que buscam lucrar com a valorização imobiliária de áreas degradadas. | N9: C | O9: A questão aborda a atuação de movimentos sociais na luta pela moradia e pelo direito à cidade. A habilidade CH-H10 exige reconhecer como a organização e a participação coletiva transformam a realidade histórico-geográfica. A alternativa C é a correta, pois identifica que a ação coletiva e organizada é o motor para redefinir o uso do espaço urbano e conquistar direitos, alterando a dinâmica da cidade. As demais alternativas focam na ineficiência estatal, na desorganização, no isolamento ou na iniciativa privada, negligenciando o papel ativo e transformador da coletividade. | P9: TRUE | Q9: 0.063829787 | R9: 2.0394089 | S9: 0.92156863 | T9: 15.462741 | U9: 5 | V9: 5 | W9: 5 | X9: 5 | Y9: 5 | Z9: 5 | AA9: O item apresenta excelente alinhamento com a habilidade-alvo CH-H10, pois o enunciado descreve de forma concreta a dinâmica de organização de movimentos sociais (assembleias, mutirões) e sua ação transformadora na realidade espacial (ocupação de prédios, reivindicação de direitos e redefinição do uso da cidade). A alternativa correta (C) capta perfeitamente essa essência, conectando a organização coletiva à transformação da realidade geográfica. Os objetos de conhecimento esperados (formas de organização social, movimentos sociais, pensamento político e ação do Estado, representação espacial) estão todos contemplados de forma integrada no texto e na alternativa correta. Os distratores são plausíveis e bem elaborados, pois cada um aponta para um elemento presente no cenário descrito (políticas públicas, legislação urbana, isolamento, iniciativa privada), mas desviam o foco do núcleo da habilidade, que é o reconhecimento da ação transformadora da coletividade. O nível de linguagem e a complexidade do tema são adequados para o Ensino Médio, exigindo compreensão de conceitos de sociologia e geografia urbana. O formato segue rigorosamente o padrão ENEM, com um enunciado contextualizado, uma pergunta implícita e cinco alternativas que exigem análise crítica e não apenas memória. | AB9: 5 | AC9: 5 | AD9: 5 | AE9: 5 | AF9: 5 | AG9: 5 | AH9: O item apresenta excelente alinhamento à habilidade CH-H10, pois exige do estudante a identificação da dinâmica organizativa dos movimentos sociais e seu impacto na transformação da realidade espacial. Os objetos de conhecimento (movimentos sociais, organização social, ação do Estado) são integralmente contemplados. Os distratores são plausíveis, abordando vertentes comuns da análise urbana (foco na falência estatal, na legislação ou no mercado), mas distinguem-se claramente da alternativa correta, que centraliza a agência coletiva. O vocabulário e a complexidade conceitual são adequados ao Ensino Médio, e a estrutura segue rigorosamente o padrão do ENEM.
A10: d4af007a-cc4c-429d-9e73-b2688cf4e9b1 | B10: com_grafo | C10: CH | D10: Ciencias Humanas e suas Tecnologias | E10: 2 | F10: CH-H10 | G10: Reconhecer a dinamica da organizacao dos movimentos sociais e a importancia da participacao da coletividade na transformacao da realidade historico-geografica. | H10: No final da década de 1980, moradores de uma região periférica de uma grande metrópole brasileira, carentes de infraestrutura básica, organizaram-se em associações de bairro. Por meio de assembleias e manifestações, ocuparam espaços públicos e reivindicaram do poder público a pavimentação de ruas, a instalação de redes de esgoto e a regularização fundiária. Ao longo dos anos, a mobilização coletiva resultou na urbanização da área e na melhoria da qualidade de vida daquela população. A situação descrita exemplifica como a organização social atua na transformação da realidade histórico-geográfica, pois: | I10: a ação individual isolada é suficiente para resolver problemas de infraestrutura urbana. | J10: a segregação espacial é superada apenas pela intervenção de empresas privadas. | K10: a participação coletiva e a mobilização social são fundamentais para pressionar o Estado e modificar o espaço. | L10: a ocupação de terras urbanas é um fenômeno espontâneo que dispensa a organização política. | M10: a transformação do espaço geográfico ocorre independentemente das relações de poder e conflitos sociais. | N10: C | O10: A questão aborda a Habilidade CH-H10 ao apresentar um cenário onde a dinâmica de um movimento social (associações de bairro, assembleias) promove a transformação da realidade histórico-geográfica (urbanização da periferia). A alternativa correta (C) identifica a importância da participação da coletividade e da organização para reivindicar direitos e alterar o espaço geográfico, enquanto as demais ignoram o papel da mobilização social ou desconsideram as relações de poder envolvidas na produção do espaço urbano. | P10: TRUE | Q10: 0.10465116 | R10: 2.8636364 | S10: 0.91489362 | T10: 16.039546 | U10: 5 | V10: 5 | W10: 5 | X10: 5 | Y10: 5 | Z10: 5 | AA10: O item apresenta excelente alinhamento com a habilidade-alvo CH-H10, pois descreve de forma concreta a dinâmica de um movimento social (organização em associações, assembleias, manifestações) e seu papel na transformação da realidade histórico-geográfica (urbanização, melhoria da qualidade de vida). Os objetos de conhecimento esperados (formas de organização social, movimentos sociais, ação do Estado e representação espacial) estão plenamente contemplados no enunciado e na alternativa correta. Os distratores são plausíveis e funcionais, pois exploram concepções errôneas comuns, como o individualismo (A), a privatização (B), a despolitização (D) e o determinismo (E), exigindo do estudante a compreensão das relações de poder e da ação coletiva. O nível de complexidade é adequado para o Ensino Médio, exigindo a análise de um caso concreto e a compreensão de conceitos sociogeográficos. A aderência ao formato ENEM é perfeita, com um enunciado contextualizado, uma pergunta que exige interpretação e análise, e alternativas que testam o domínio dos conceitos-chave da habilidade. | AB10: 5 | AC10: 5 | AD10: 5 | AE10: 5 | AF10: 5 | AG10: 5 | AH10: O item apresenta excelente alinhamento à habilidade CH-H10, pois descreve um cenário concreto de organização social (movimentos de bairro) e solicita o reconhecimento do papel dessa coletividade na transformação do espaço urbano. Os objetos de conhecimento (movimentos sociais, ação do Estado) são integralmente abordados. Os distratores são plausíveis, representando visões reducionistas ou equivocadas sobre a produção do espaço (individualismo, espontaneísmo, ausência de conflito), o que garante a validade da avaliação. O nível de linguagem e a complexidade cognitiva são adequados ao Ensino Médio, e o formato segue rigorosamente o padrão do ENEM, com enunciado contextualizado e comando claro de associação.
A11: 0da7d921-2968-4a9c-bdd0-8a6907c5a9d9 | B11: com_grafo | C11: CH | D11: Ciencias Humanas e suas Tecnologias | E11: 2 | F11: CH-H10 | G11: Reconhecer a dinamica da organizacao dos movimentos sociais e a importancia da participacao da coletividade na transformacao da realidade historico-geografica. | H11: Nas últimas décadas, as grandes metrópoles brasileiras têm testemunhado o surgimento de novas formas de organização social em resposta à desigualdade urbana e à especulação imobiliária. Um exemplo significativo é a ocupação de edifícios abandonados no centro das cidades por movimentos de luta por moradia. Em uma determinada capital, famílias organizadas ocuparam um antigo hotel vazio há mais de dez anos. Através de assembleias semanais, os moradores estabeleceram regras de convivência, criaram cooperativas de limpeza e alimentação, e transformaram o espaço, antes degradado, em um local de moradia digna, cultura e resistência. Essa ação coletiva pressionou o poder público a iniciar um diálogo para a regularização fundiária do imóvel. | I11: Demonstra que a invasão de propriedades privadas é a única solução viável para a crise habitacional, independentemente da organização política. | J11: Ilustra a capacidade do Estado em resolver isoladamente os problemas de segregação espacial, sem a necessidade de pressão popular. | K11: Evidencia a dinâmica dos movimentos sociais na transformação da realidade urbana por meio da participação coletiva e da redefinição do uso do espaço. | L11: Reflete a desorganização social nas cidades, onde a ausência de leis impede que a população exerça sua cidadania plena. | M11: Indica que a valorização do imobiliário no centro urbano ocorre naturalmente, independentemente das ações de reivindicação dos movimentos sociais. | N11: C | O11: A questão descreve uma situação concreta de atuação de um movimento social urbano (luta por moradia) que, por meio da organização e participação coletiva (assembleias, cooperativas), altera a função e o significado de um espaço geográfico (edifício abandonado vira moradia) e interfere na esfera pública. A alternativa C é a correta pois identifica exatamente essa dinâmica de transformação da realidade histórico-geográfica pela ação da coletividade, conforme exige a Habilidade CH-H10. | P11: TRUE | Q11: 0.077586207 | R11: 2.257732 | S11: 0.90625 | T11: 15.652866 | U11: 5 | V11: 5 | W11: 5 | X11: 5 | Y11: 5 | Z11: 5 | AA11: O item apresenta excelente alinhamento com a habilidade-alvo CH-H10, pois descreve de forma concreta a dinâmica de organização de um movimento social (assembleias, cooperativas) e sua importância na transformação da realidade histórico-geográfica (ocupação de um edifício abandonado, pressão pelo diálogo e regularização fundiária). Os objetos de conhecimento esperados (formas de organização social, movimentos sociais, ação do Estado e representação espacial) estão plenamente contemplados no enunciado e na alternativa correta. Os distratores (A, B, D, E) são plausíveis, pois exploram visões simplistas, reducionistas ou contrárias aos princípios da ação coletiva, exigindo do estudante a capacidade de discernir a análise correta. A linguagem e o contexto são adequados ao Ensino Médio, abordando um tema pertinente à realidade brasileira. O formato segue as características do ENEM, com um enunciado contextualizado e uma alternativa correta que exige a compreensão de conceitos complexos, em detrimento de respostas literais ou memorísticas. | AB11: 5 | AC11: 5 | AD11: 5 | AE11: 5 | AF11: 5 | AG11: 5 | AH11: O item apresenta excelente alinhamento à habilidade CH-H10, pois exige do estudante o reconhecimento da organização coletiva (assembleias, cooperativas) e sua capacidade de transformar a realidade urbana e a relação com o Estado. Os objetos de conhecimento (movimentos sociais, organização social) são plenamente contemplados. Os distratores são plausíveis, explorando interpretações equivocadas comuns (como a desorganização ou a onipotência estatal), mas são refutáveis pelo texto. O nível de complexidade e a linguagem são adequados ao Ensino Médio, e o formato segue rigorosamente o padrão do ENEM, com enunciado contextualizado e alternativas que exigem análise e síntese.
A12: 3ffb29f7-9a8e-4eff-84e2-ef225722d2ce | B12: com_grafo | C12: CH | D12: Ciencias Humanas e suas Tecnologias | E12: 3 | F12: CH-H11 | G12: Identificar registros de praticas de grupos sociais no tempo e no espaco. | H12: No início do século XX, o Rio de Janeiro passou por profundas reformas urbanas, marcadas pela demolição de cortiços e casarões antigos. Um relatório médico-sanitário da época descrevia a situação: "A concentração de operários em habitações coletivas insalubres no centro da cidade favorece a propagação de moléstias. Para o progresso da capital, é imperativo transferir essa população para zonas afastadas, onde possam viver de forma mais saudável, longe do núcleo civilizado." O registro apresentado evidencia uma prática de organização espacial que resultou na | I12: valorização imobiliária das áreas periféricas pela classe operária. | J12: manutenção da população pobre no centro urbano para facilitar o trabalho. | K12: criação de políticas de habitação popular integradas ao centro da metrópole. | L12: segregação socioespacial, empurrando os trabalhadores para a periferia. | M12: erradicação das epidemias através da melhoria das condições dos cortiços. | N12: D | O12: A habilidade CH-H11 exige identificar registros de práticas de grupos sociais no tempo e no espaço. O enunciado apresenta um documento histórico (relatório) que registra a prática das elites políticas e sanitárias do início do século XX no Rio de Janeiro. Ao analisar o documento, percebe-se que a justificativa higienista foi utilizada para remover a população trabalhadora do centro, impondo uma dinâmica de segregação socioespacial que forçou esses grupos para as áreas periféricas da cidade. | P12: TRUE | Q12: 0.025316456 | R12: 1.106383 | S12: 0.95180723 | T12: 13.315334 | U12: 4.8 | V12: 5 | W12: 5 | X12: 4 | Y12: 5 | Z12: 5 | AA12: O item apresenta excelente alinhamento com a habilidade CH-H11, pois o enunciado, ao apresentar um relatório histórico, exige que o aluno identifique uma prática de organização espacial específica (a remoção da população operária do centro do Rio de Janeiro) e a contextualize no tempo (início do século XX) e no espaço (centro vs. periferia). Os objetos de conhecimento (formas de organização social, ação do Estado) são perfeitamente adequados e necessários para a resolução do item. Os distratores são plausíveis, pois exploram interpretações equivocadas mas possíveis do texto (como a manutenção no centro ou a valorização das periferias), com exceção do distrator E, que se desvia do foco do documento (a remoção, não a melhoria dos cortiços). O nível de complexidade é adequado para o Ensino Médio, exigindo análise de fonte histórica e compreensão de conceitos como segregação socioespacial. O formato segue rigorosamente as características do ENEM, com enunciado contextualizado, baseado em documento e alternativa correta que exige síntese e interpretação crítica. | AB12: 4.8 | AC12: 5 | AD12: 5 | AE12: 4 | AF12: 5 | AG12: 5 | AH12: O item apresenta um registro histórico (relatório médico-sanitário) que evidencia uma prática de grupo social (elites e sanitaristas) no tempo e espaço (Rio de Janeiro, início do século XX), exigindo do aluno a identificação da consequência socioespacial dessa prática (segregação). Há alinhamento total à habilidade CH-H11 e aos objetos de conhecimento (ação do Estado, pensamento político). Os distratores são plausíveis, exigindo leitura atenta para distinguir a justificativa ideológica do texto da realidade histórica. O vocabulário e a complexidade são adequados ao Ensino Médio, e o formato segue rigorosamente o padrão ENEM.
A13: 7815c0d1-6858-4457-9e28-2548c76379eb | B13: com_grafo | C13: CH | D13: Ciencias Humanas e suas Tecnologias | E13: 3 | F13: CH-H11 | G13: Identificar registros de praticas de grupos sociais no tempo e no espaco. | H13: Em grandes metrópoles brasileiras, é comum observar um padrão de ocupação do solo em que as áreas centrais, dotadas de melhor infraestrutura e serviços, são ocupadas por camadas de maior renda, enquanto a população de baixa renda reside em periferias distantes, frequentemente carentes de equipamentos urbanos. Essa morfologia urbana não é aleatória, mas fruto de processos históricos de valorização imobiliária e ausência de políticas habitacionais inclusivas. A configuração espacial descrita no texto constitui um registro material da prática de: | I13: Mobilidade pendular equilibrada entre centro e periferia. | J13: Segregação socioespacial fundamentada na diferenciação de renda. | K13: Democratização do acesso à terra urbanizada para todos os grupos. | L13: Desconcentração das atividades industriais nos bairros centrais. | M13: Fixação das elites econômicas nas regiões periféricas da cidade. | N13: B | O13: A habilidade CH-H11 exige identificar registros de práticas de grupos sociais no tempo e no espaço. O enunciado descreve a configuração espacial das cidades brasileiras (o registro), evidenciando a prática de segregação socioespacial. Essa prática reflete a ação de grupos sociais (mercado imobiliário e poder público) e a condição de diferentes classes (elites no centro, trabalhadores na periferia), organizando o espaço urbano de acordo com a capacidade econômica. | P13: TRUE | Q13: 0.027027027 | R13: 1.1650485 | S13: 0.96103896 | T13: 14.243361 | U13: 4.8 | V13: 5 | W13: 5 | X13: 4 | Y13: 5 | Z13: 5 | AA13: O item demonstra excelente alinhamento com a habilidade CH-H11, pois a descrição da morfologia urbana funciona como um 'registro material' que exige a identificação da prática social (segregação socioespacial) que o produziu. Os objetos de conhecimento (organização social, ação do Estado) são perfeitamente contemplados na análise da configuração espacial. Os distratores são plausíveis, pois exploram conceitos relacionados à organização urbana (mobilidade, desconcentração industrial), mas são semanticamente distintos da prática central descrita. O nível de linguagem e a complexidade conceitual são adequados ao Ensino Médio. O formato segue rigorosamente as especificações do ENEM, com um enunciado contextualizado e uma pergunta que exige a análise e interpretação do texto para a seleção da alternativa correta. | AB13: 5 | AC13: 5 | AD13: 5 | AE13: 5 | AF13: 5 | AG13: 5 | AH13: O item apresenta excelente alinhamento à habilidade CH-H11, pois solicita ao aluno identificar, a partir de uma configuração espacial descrita (morfologia urbana), a prática social subjacente (segregação socioespacial). O enunciado contextualiza o fenômeno no tempo e no espaço, conforme exigido. Os objetos de conhecimento (organização social, ação do Estado) são adequadamente abordados ao discutir a distribuição da população e a falta de políticas públicas. Os distratores são plausíveis e relacionados à temática urbana, exigindo leitura atenta e domínio conceitual para serem descartados. O vocabulário e a complexidade são adequados ao Ensino Médio, e o formato segue rigorosamente o padrão do ENEM.
... A1646: 333aa7a9-d89a-4fb6-b8f5-53b0afe192fc | B1646: sem_grafo | C1646: MT | D1646: Matematica e suas Tecnologias | E1646: 1 | F1646: MT-H1 | G1646: Reconhecer, no contexto social, diferentes significados e representacoes dos numeros e operacoes - naturais, inteiros, racionais ou reais. | H1646: Um jovem abriu uma conta corrente e, ao verificar o primeiro extrato, percebeu que o saldo estava representado pelo número -R$ 120,00. No contexto bancário, o sinal negativo indica que o cliente está devendo dinheiro ao banco. Para tentar regularizar a situação, ele fez um depósito de R$ 50,00 e, no mesmo dia, realizou uma compra no débito automático de R$ 80,00. Qual é o novo saldo da conta e o que ele representa? | I1646: R$ 10,00, indicando que o jovem agora tem saldo positivo disponível para saque. | J1646: -R$ 150,00, indicando que o jovem aumentou sua dívida para R$ 150,00. | K1646: -R$ 90,00, indicando que a dívida do jovem diminuiu para R$ 90,00. | L1646: R$ 250,00, indicando que o jovem tem um crédito total de R$ 250,00. | M1646: -R$ 210,00, indicando que o jovem está devendo R$ 210,00 ao banco. | N1646: B | O1646: A habilidade MT-H1 é avaliada ao exigir o reconhecimento do significado social dos números inteiros (negativos e positivos) e das operações de adição e subtração. O saldo inicial (-120) representa uma dívida. O depósito (+50) é uma adição que reduz a dívida (-120 + 50 = -70). A compra no débito (-80) é uma subtração que aumenta a dívida (-70 - 80 = -150). Portanto, o resultado -150 representa uma dívida de R$ 150,00. | P1646: TRUE | Q1646: 0 | R1646: 0 | S1646: 0.62820513 | T1646: 9.565098 | U1646: 5 | V1646: 5 | W1646: 5 | X1646: 5 | Y1646: 5 | Z1646: 5 | AA1646: O item apresenta excelente alinhamento com a habilidade MT-H1, pois exige o reconhecimento do significado social do número negativo (dívida) e de operações matemáticas (adição e subtração) em um contexto financeiro real. Os objetos de conhecimento (conhecimentos numéricos) são perfeitamente adequados e aplicados. Os distratores são plausíveis, pois exploram erros comuns de interpretação de sinais e ordem das operações (ex: somar os valores absolutos, interpretar o resultado final como positivo). O nível de complexidade é adequado para o Ensino Médio, exigindo a compreensão de conceitos de números inteiros e suas aplicações práticas. O formato segue rigorosamente as especificações do ENEM, com enunciado contextualizado, alternativas claras e uma justificativa objetiva para o gabarito. | AB1646: 4.6 | AC1646: 5 | AD1646: 5 | AE1646: 4 | AF1646: 4 | AG1646: 5 | AH1646: O item avalia plenamente a habilidade MT-H1 ao contextualizar operações com números inteiros em uma situação bancária realista, exigindo a interpretação do sinal negativo como dívida. Os objetos de conhecimento (números inteiros e operações) são adequados. Os distratores A, C e D são plausíveis, pois representam erros comuns de interpretação de sinais (tratar débito como crédito, inverter operações ou ignorar sinais), porém o distrator E (-R$ 210,00) não parece decorrer de um erro aritmético lógico com os valores apresentados, reduzindo ligeiramente a nota. O nível de escolaridade é adequado, embora a questão seja considerada fácil para o Ensino Médio, tratando de conteúdo básico (operações com inteiros) frequente nas primeiras questões da prova. O formato adere perfeitamente ao padrão ENEM.
A1647: ef9c02e6-d839-482b-b619-27c7f7301100 | B1647: sem_grafo | C1647: MT | D1647: Matematica e suas Tecnologias | E1647: 1 | F1647: MT-H1 | G1647: Reconhecer, no contexto social, diferentes significados e representacoes dos numeros e operacoes - naturais, inteiros, racionais ou reais. | H1647: Um aplicativo de transporte individual permite que o usuário faça viagens mesmo sem saldo suficiente, gerando um limite de crédito. O saldo do usuário é representado por números reais, onde valores positivos indicam créditos disponíveis e valores negativos indicam débito (dívida) com a plataforma. Maria tinha um saldo inicial de R$ 15,00. Ela fez uma viagem de R$ 22,00, depois depositou R$ 30,00 e, em seguida, fez outra viagem de R$ 45,00. Qual é o saldo final de Maria e o que esse valor significa no contexto do aplicativo? | I1647: R$ 22,00, indicando que ela tem crédito disponível para uso. | J1647: -R$ 22,00, indicando que ela está devendo esse valor à plataforma. | K1647: R$ 8,00, indicando o saldo restante após o depósito. | L1647: -R$ 8,00, indicando que ela excedeu o limite de crédito. | M1647: R$ 67,00, indicando o total gasto nas viagens. | N1647: B | O1647: A questão exige a habilidade de reconhecer o significado de números inteiros (e operações com eles) em um contexto social (finanças pessoais em um aplicativo). O cálculo é 15 - 22 + 30 - 45 = -22. O sinal negativo no resultado não indica apenas uma posição na reta numérica, mas, neste contexto, representa especificamente um débito ou dívida contraída junto ao serviço. | P1647: TRUE | Q1647: 0.018518519 | R1647: 0.82352941 | S1647: 0.62790698 | T1647: 9.9077445 | U1647: 5 | V1647: 5 | W1647: 5 | X1647: 5 | Y1647: 5 | Z1647: 5 | AA1647: O item apresenta excelente alinhamento com a habilidade-alvo MT-H1, pois exige a interpretação do significado social de um número real (negativo) em um contexto financeiro contemporâneo (aplicativo de transporte). A habilidade de reconhecer que o valor negativo representa um débito, e não apenas uma posição na reta numérica, é central. Os objetos de conhecimento (conhecimentos numéricos) são perfeitamente adequados e aplicados na resolução do problema. Os distratores são plausíveis e bem elaborados: a alternativa A confunde o valor absoluto do resultado com seu significado; a C apresenta um resultado de um cálculo parcial (após o depósito); a D usa um valor absoluto incorreto; e a E soma os gastos, ignorando o saldo inicial e o depósito, representando erros comuns de interpretação de contexto. O nível de complexidade é adequado para o Ensino Médio, envolvendo operações com números inteiros e a interpretação de um resultado em um cenário da vida real. O formato segue rigorosamente as especificações do ENEM, com enunciado contextualizado, alternativas que exigem análise crítica e não apenas cálculo, e uma justificativa que conecta a resposta correta à habilidade avaliada.
A1648: b28dcda8-51b3-4810-8df7-872954cee891 | B1648: sem_grafo | C1648: MT | D1648: Matematica e suas Tecnologias | E1648: 3 | F1648: MT-H10 | G1648: Identificar relacoes entre grandezas e unidades de medida. | H1648: Em uma obra de construção civil, o engenheiro responsável precisa calcular a densidade de um bloco de concreto para garantir a estabilidade da fundação. A densidade é uma grandeza física definida pela razão entre a massa de um corpo e o volume por ele ocupado. No laboratório de ensaios, a massa do bloco foi medida em quilogramas (kg) e seu volume em metros cúbicos (m³). Com base na relação matemática entre as grandezas envolvidas, qual é a unidade de medida adequada para expressar a densidade desse material? | I1648: kg/m³ | J1648: m³/kg | K1648: kg·m³ | L1648: kg/m² | M1648: m²/kg | N1648: A | O1648: A habilidade MT-H10 é avaliada ao identificar que a unidade de uma grandeza derivada (densidade) resulta da relação entre as unidades das grandezas fundamentais que a compõem (massa e volume). Como a densidade é a divisão da massa pelo volume, sua unidade é dada pela divisão da unidade de massa (kg) pela unidade de volume (m³), resultando em kg/m³. | P1648: TRUE | Q1648: 0.048780488 | R1648: 1.260274 | S1648: 0.71929825 | T1648: 11.979478 | U1648: 4.8 | V1648: 5 | W1648: 5 | X1648: 4 | Y1648: 5 | Z1648: 5 | AA1648: O item apresenta excelente alinhamento com a habilidade MT-H10, pois o cerne da questão é a identificação da relação entre as grandezas (massa e volume) para determinar a unidade de medida da grandeza derivada (densidade). Os objetos de conhecimento, embora listados como 'Conhecimentos geometricos', são na verdade de Física (grandezas e unidades), o que representa uma pequena inadequação. No entanto, o contexto da construção civil e a definição fornecida no enunciado tornam o item plausível e acessível para o Ensino Médio. Os distratores (B, C, D, E) são plausíveis, pois representam inversões ou combinações incorretas das unidades, exigindo que o aluno compreenda a natureza da relação (divisão) entre as grandezas. O item está perfeitamente adequado ao nível de escolaridade e ao formato do ENEM, pois contextualiza o conhecimento em uma situação-problema real e utiliza linguagem clara e objetiva. | AB1648: 5 | AC1648: 5 | AD1648: 5 | AE1648: 5 | AF1648: 5 | AG1648: 5 | AH1648: O item avalia plenamente a habilidade MT-H10, pois solicita a identificação da unidade de medida resultante da relação entre massa e volume (densidade). Os objetos de conhecimento geométricos são contemplados através da grandeza volume (m³). Os distratores são plausíveis, explorando erros comuns de operação (inversão, multiplicação) e de dimensão (confusão entre área e volume). O nível de dificuldade é adequado ao Ensino Médio e o formato segue rigorosamente o padrão do ENEM, com contextualização realista e estrutura de cinco alternativas.
